[2025-04-04 07:35:39][INFO] Installation des dépendances Python...
[2025-04-04 07:35:39][ERROR] Échec de l'installation: Fichier requirements.txt introuvable
[2025-04-04 07:35:39][INFO] Conversion des fichiers hérités...
[2025-04-04 07:35:39][ERROR] Erreur de conversion: The term 'C:\Python\Python311\python.exe' is not recognized as a name of a cmdlet, function, script file, or executable program.
Check the spelling of the name, or if a path was included, verify that the path is correct and try again.
[2025-04-04 07:35:55][ERROR] Erreur de configuration: The term 'C:\Python\Python311\python.exe' is not recognized as a name of a cmdlet, function, script file, or executable program.
Check the spelling of the name, or if a path was included, verify that the path is correct and try again.
[2025-04-04 07:35:59][INFO] Installation des dépendances Python...
[2025-04-04 07:35:59][ERROR] Échec de l'installation: Fichier requirements.txt introuvable
[2025-04-04 07:36:21][ERROR] Erreur de configuration: The term 'C:\Python\Python311\python.exe' is not recognized as a name of a cmdlet, function, script file, or executable program.
Check the spelling of the name, or if a path was included, verify that the path is correct and try again.
[2025-04-04 07:36:32][INFO] Installation des dépendances Python...
[2025-04-04 07:36:32][ERROR] Échec de l'installation: Fichier requirements.txt introuvable
[2025-04-04 07:36:45][INFO] Conversion des fichiers hérités...
[2025-04-04 07:36:45][ERROR] Erreur de conversion: The term 'C:\Python\Python311\python.exe' is not recognized as a name of a cmdlet, function, script file, or executable program.
Check the spelling of the name, or if a path was included, verify that the path is correct and try again.
[2025-04-04 07:36:58][INFO] Lancement de l'analyse complète...
[2025-04-04 07:36:58][ERROR] Échec de l'analyse: The term 'C:\Python\Python311\python.exe' is not recognized as a name of a cmdlet, function, script file, or executable program.
Check the spelling of the name, or if a path was included, verify that the path is correct and try again.
[2025-04-04 07:37:26][INFO] Démarrage de l'interface web sur le port 5000...
[2025-04-04 07:37:36][SUCCESS] Interface web démarrée. Ctrl+C pour arrêter.
[2025-04-04 07:38:37][ERROR] Erreur de configuration: The term 'C:\Python\Python311\python.exe' is not recognized as a name of a cmdlet, function, script file, or executable program.
Check the spelling of the name, or if a path was included, verify that the path is correct and try again.
[2025-04-04 07:41:59][ERROR] Erreur de configuration: Python 3.x requis
[2025-04-04 07:42:16][INFO] Installation des dépendances Python...
[2025-04-04 07:42:16][ERROR] Échec de l'installation: Unable to create process using 'C:\Python313\python.exe -m pip install -r C:\Users\HP\Desktop\Revoir-Histoire-Anciens-Batisseurs-master\requirements.txt': Le fichier spÚcifiÚ est introuvable. System.Management.Automation.RemoteException System.Management.Automation.RemoteException
[2025-04-04 07:42:30][INFO] Conversion des fichiers hérités...
[2025-04-04 07:42:30][SUCCESS] Conversion terminée avec succès
[2025-04-04 07:42:49][INFO] Lancement de l'analyse complète...
[2025-04-04 07:42:49][ERROR] Échec de l'analyse: Erreur lors de l'analyse
[2025-04-04 07:43:28][ERROR] Erreur de démarrage: Exception calling "Connect" with "2" argument(s): "Aucune connexion n’a pu être établie car l’ordinateur cible l’a expressément refusée. [::ffff:127.0.0.1]:5000"
[2025-04-04 07:43:45][ERROR] Erreur de configuration: Python 3.x requis
[2025-04-04 08:20:37][ERROR] Erreur de configuration: Module flask manquant
[2025-04-04 08:20:42][INFO] Installation des dépendances Python...
[2025-04-04 08:20:42][ERROR] Échec de l'installation: Python path configuration:   PYTHONHOME = 'C:\Python\python311\python-3.11.0-embed-amd64'   PYTHONPATH = 'C:\Python\python311\python-3.11.0-embed-amd64\Lib'   program name = 'C:\Python312\python.exe'   isolated = 0   environment = 1   user site = 1   safe_path = 0   import site = 1   is in build tree = 0   stdlib dir = 'C:\Python\python311\python-3.11.0-embed-amd64\Lib'   sys._base_executable = 'C:\\Python312\\python.exe'   sys.base_prefix = 'C:\\Python\\python311\\python-3.11.0-embed-amd64'   sys.base_exec_prefix = 'C:\\Python\\python311\\python-3.11.0-embed-amd64'   sys.platlibdir = 'DLLs'   sys.executable = 'C:\\Python312\\python.exe'   sys.prefix = 'C:\\Python\\python311\\python-3.11.0-embed-amd64'   sys.exec_prefix = 'C:\\Python\\python311\\python-3.11.0-embed-amd64'   sys.path = [     'C:\\Python\\python311\\python-3.11.0-embed-amd64\\Lib',     'C:\\Python312\\python312.zip',     'C:\\Python\\python311\\python-3.11.0-embed-amd64\\DLLs',     'C:\\Python\\python311\\python-3.11.0-embed-amd64\\Lib',     'C:\\Python312',   ] Fatal Python error: init_fs_encoding: failed to get the Python codec of the filesystem encoding Python runtime state: core initialized ModuleNotFoundError: No module named 'encodings' System.Management.Automation.RemoteException Current thread 0x000050f4 (most recent call first):   <no Python frame>
[2025-04-04 08:24:52][INFO] Installation des dépendances Python...
[2025-04-04 08:24:52][ERROR] Échec de l'installation: Python path configuration:   PYTHONHOME = 'C:\Python\python311\python-3.11.0-embed-amd64'   PYTHONPATH = 'C:\Python\python311\python-3.11.0-embed-amd64\Lib'   program name = 'C:\Python312\python.exe'   isolated = 0   environment = 1   user site = 1   safe_path = 0   import site = 1   is in build tree = 0   stdlib dir = 'C:\Python\python311\python-3.11.0-embed-amd64\Lib'   sys._base_executable = 'C:\\Python312\\python.exe'   sys.base_prefix = 'C:\\Python\\python311\\python-3.11.0-embed-amd64'   sys.base_exec_prefix = 'C:\\Python\\python311\\python-3.11.0-embed-amd64'   sys.platlibdir = 'DLLs'   sys.executable = 'C:\\Python312\\python.exe'   sys.prefix = 'C:\\Python\\python311\\python-3.11.0-embed-amd64'   sys.exec_prefix = 'C:\\Python\\python311\\python-3.11.0-embed-amd64'   sys.path = [     'C:\\Python\\python311\\python-3.11.0-embed-amd64\\Lib',     'C:\\Python312\\python312.zip',     'C:\\Python\\python311\\python-3.11.0-embed-amd64\\DLLs',     'C:\\Python\\python311\\python-3.11.0-embed-amd64\\Lib',     'C:\\Python312',   ] Fatal Python error: init_fs_encoding: failed to get the Python codec of the filesystem encoding Python runtime state: core initialized ModuleNotFoundError: No module named 'encodings' System.Management.Automation.RemoteException Current thread 0x00001ba8 (most recent call first):   <no Python frame>
[2025-04-04 08:25:05][ERROR] Erreur de configuration: Module flask manquant
[2025-04-04 08:25:16][INFO] Conversion des fichiers hérités...
[2025-04-04 08:25:16][SUCCESS] Conversion terminée avec succès
[2025-04-04 08:25:57][INFO] Lancement de l'analyse complète...
[2025-04-04 08:25:57][ERROR] Échec de l'analyse: Erreur lors de l'analyse
[2025-04-04 08:26:23][INFO] Traitement des cartes historiques (Tâche: all)...
[2025-04-04 08:26:23][ERROR] Échec du traitement: Erreur pendant le traitement
[2025-04-04 08:26:51][ERROR] Erreur de démarrage: Exception calling "Connect" with "2" argument(s): "Aucune connexion n’a pu être établie car l’ordinateur cible l’a expressément refusée. [::ffff:127.0.0.1]:5000"
[2025-04-04 08:55:21][ERROR] Erreur de configuration: Module flask manquant
[2025-04-04 08:55:25][INFO] Installation des dépendances Python...
[2025-04-04 08:55:28][ERROR] Échec de l'installation: System.Management.Automation.RemoteException [notice] A new release of pip is available: 24.3.1 -> 25.0.1 [notice] To update, run: python.exe -m pip install --upgrade pip ERROR: Invalid requirement: '@"': Expected package name at the start of dependency specifier     @"     ^ (from line 2 of C:\Users\HP\Desktop\Revoir-Histoire-Anciens-Batisseurs-master\requirements.txt)
[2025-04-04 08:55:46][INFO] Installation des dépendances Python...
[2025-04-04 08:55:48][ERROR] Échec de l'installation: System.Management.Automation.RemoteException [notice] A new release of pip is available: 24.3.1 -> 25.0.1 [notice] To update, run: python.exe -m pip install --upgrade pip ERROR: Invalid requirement: '@"': Expected package name at the start of dependency specifier     @"     ^ (from line 2 of C:\Users\HP\Desktop\Revoir-Histoire-Anciens-Batisseurs-master\requirements.txt)
[2025-04-04 08:57:05][INFO] Installation des dépendances Python...
[2025-04-04 08:57:24][ERROR] Échec de l'installation: Collecting flask==2.0.1 (from -r C:\Users\HP\Desktop\Revoir-Histoire-Anciens-Batisseurs-master\requirements.txt (line 1))   Downloading Flask-2.0.1-py3-none-any.whl.metadata (3.8 kB) Collecting pandas==1.3.0 (from -r C:\Users\HP\Desktop\Revoir-Histoire-Anciens-Batisseurs-master\requirements.txt (line 2))   Downloading pandas-1.3.0.tar.gz (4.7 MB)      ---------------------------------------- 4.7/4.7 MB 71.9 MB/s eta 0:00:00   Installing build dependencies: started   Installing build dependencies: finished with status 'error'   error: subprocess-exited-with-error      pip subprocess to install build dependencies did not run successfully.   exit code: 2      [118 lines of output]   Ignoring numpy: markers 'python_version == "3.7" and (platform_machine != "arm64" or platform_system != "Darwin") and platform_machine != "aarch64"' don't match your environment   Ignoring numpy: markers 'python_version == "3.8" and (platform_machine != "arm64" or platform_system != "Darwin") and platform_machine != "aarch64"' don't match your environment   Ignoring numpy: markers 'python_version == "3.7" and platform_machine == "aarch64"' don't match your environment   Ignoring numpy: markers 'python_version == "3.8" and platform_machine == "aarch64"' don't match your environment   Ignoring numpy: markers 'python_version == "3.8" and platform_machine == "arm64" and platform_system == "Darwin"' don't match your environment   Ignoring numpy: markers 'python_version == "3.9" and platform_machine == "arm64" and platform_system == "Darwin"' don't match your environment   Collecting setuptools>=38.6.0     Using cached setuptools-78.1.0-py3-none-any.whl.metadata (6.6 kB)   Collecting wheel     Using cached wheel-0.45.1-py3-none-any.whl.metadata (2.3 kB)   Collecting Cython<3,>=0.29.21     Downloading Cython-0.29.37-py2.py3-none-any.whl.metadata (3.1 kB)   Collecting numpy==1.19.3     Downloading numpy-1.19.3.zip (7.3 MB)        ---------------------------------------- 7.3/7.3 MB 64.7 MB/s eta 0:00:00     Installing build dependencies: started     Installing build dependencies: finished with status 'done'     Getting requirements to build wheel: started     Getting requirements to build wheel: finished with status 'done'   ERROR: Exception:   Traceback (most recent call last):     File "C:\Python312\Lib\site-packages\pip\_internal\cli\base_command.py", line 105, in _run_wrapper       status = _inner_run()                ^^^^^^^^^^^^     File "C:\Python312\Lib\site-packages\pip\_internal\cli\base_command.py", line 96, in _inner_run       return self.run(options, args)              ^^^^^^^^^^^^^^^^^^^^^^^     File "C:\Python312\Lib\site-packages\pip\_internal\cli\req_command.py", line 67, in wrapper       return func(self, options, args)              ^^^^^^^^^^^^^^^^^^^^^^^^^     File "C:\Python312\Lib\site-packages\pip\_internal\commands\install.py", line 379, in run       requirement_set = resolver.resolve(                         ^^^^^^^^^^^^^^^^^     File "C:\Python312\Lib\site-packages\pip\_internal\resolution\resolvelib\resolver.py", line 95, in resolve       result = self._result = resolver.resolve(                               ^^^^^^^^^^^^^^^^^     File "C:\Python312\Lib\site-packages\pip\_vendor\resolvelib\resolvers.py", line 546, in resolve       state = resolution.resolve(requirements, max_rounds=max_rounds)               ^^^^^^^^^^^^^^^^^^^^^^^^^^^^^^^^^^^^^^^^^^^^^^^^^^^^^^^     File "C:\Python312\Lib\site-packages\pip\_vendor\resolvelib\resolvers.py", line 397, in resolve       self._add_to_criteria(self.state.criteria, r, parent=None)     File "C:\Python312\Lib\site-packages\pip\_vendor\resolvelib\resolvers.py", line 173, in _add_to_criteria       if not criterion.candidates:              ^^^^^^^^^^^^^^^^^^^^     File "C:\Python312\Lib\site-packages\pip\_vendor\resolvelib\structs.py", line 156, in __bool__       return bool(self._sequence)              ^^^^^^^^^^^^^^^^^^^^     File "C:\Python312\Lib\site-packages\pip\_internal\resolution\resolvelib\found_candidates.py", line 174, in __bool__       return any(self)              ^^^^^^^^^     File "C:\Python312\Lib\site-packages\pip\_internal\resolution\resolvelib\found_candidates.py", line 162, in <genexpr>       return (c for c in iterator if id(c) not in self._incompatible_ids)                          ^^^^^^^^     File "C:\Python312\Lib\site-packages\pip\_internal\resolution\resolvelib\found_candidates.py", line 53, in _iter_built       candidate = func()                   ^^^^^^     File "C:\Python312\Lib\site-packages\pip\_internal\resolution\resolvelib\factory.py", line 187, in _make_candidate_from_link       base: Optional[BaseCandidate] = self._make_base_candidate_from_link(                                       ^^^^^^^^^^^^^^^^^^^^^^^^^^^^^^^^^^^^     File "C:\Python312\Lib\site-packages\pip\_internal\resolution\resolvelib\factory.py", line 233, in _make_base_candidate_from_link       self._link_candidate_cache[link] = LinkCandidate(                                          ^^^^^^^^^^^^^^     File "C:\Python312\Lib\site-packages\pip\_internal\resolution\resolvelib\candidates.py", line 304, in __init__       super().__init__(     File "C:\Python312\Lib\site-packages\pip\_internal\resolution\resolvelib\candidates.py", line 159, in __init__       self.dist = self._prepare()                   ^^^^^^^^^^^^^^^     File "C:\Python312\Lib\site-packages\pip\_internal\resolution\resolvelib\candidates.py", line 236, in _prepare       dist = self._prepare_distribution()              ^^^^^^^^^^^^^^^^^^^^^^^^^^^^     File "C:\Python312\Lib\site-packages\pip\_internal\resolution\resolvelib\candidates.py", line 315, in _prepare_distribution       return preparer.prepare_linked_requirement(self._ireq, parallel_builds=True)              ^^^^^^^^^^^^^^^^^^^^^^^^^^^^^^^^^^^^^^^^^^^^^^^^^^^^^^^^^^^^^^^^^^^^^     File "C:\Python312\Lib\site-packages\pip\_internal\operations\prepare.py", line 527, in prepare_linked_requirement       return self._prepare_linked_requirement(req, parallel_builds)              ^^^^^^^^^^^^^^^^^^^^^^^^^^^^^^^^^^^^^^^^^^^^^^^^^^^^^^     File "C:\Python312\Lib\site-packages\pip\_internal\operations\prepare.py", line 642, in _prepare_linked_requirement       dist = _get_prepared_distribution(              ^^^^^^^^^^^^^^^^^^^^^^^^^^^     File "C:\Python312\Lib\site-packages\pip\_internal\operations\prepare.py", line 72, in _get_prepared_distribution       abstract_dist.prepare_distribution_metadata(     File "C:\Python312\Lib\site-packages\pip\_internal\distributions\sdist.py", line 56, in prepare_distribution_metadata       self._install_build_reqs(finder)     File "C:\Python312\Lib\site-packages\pip\_internal\distributions\sdist.py", line 126, in _install_build_reqs       build_reqs = self._get_build_requires_wheel()                    ^^^^^^^^^^^^^^^^^^^^^^^^^^^^^^^^     File "C:\Python312\Lib\site-packages\pip\_internal\distributions\sdist.py", line 103, in _get_build_requires_wheel       return backend.get_requires_for_build_wheel()              ^^^^^^^^^^^^^^^^^^^^^^^^^^^^^^^^^^^^^^     File "C:\Python312\Lib\site-packages\pip\_internal\utils\misc.py", line 701, in get_requires_for_build_wheel       return super().get_requires_for_build_wheel(config_settings=cs)              ^^^^^^^^^^^^^^^^^^^^^^^^^^^^^^^^^^^^^^^^^^^^^^^^^^^^^^^^     File "C:\Python312\Lib\site-packages\pip\_vendor\pyproject_hooks\_impl.py", line 166, in get_requires_for_build_wheel       return self._call_hook('get_requires_for_build_wheel', {              ^^^^^^^^^^^^^^^^^^^^^^^^^^^^^^^^^^^^^^^^^^^^^^^^^     File "C:\Python312\Lib\site-packages\pip\_vendor\pyproject_hooks\_impl.py", line 321, in _call_hook       raise BackendUnavailable(data.get('traceback', ''))   pip._vendor.pyproject_hooks._impl.BackendUnavailable: Traceback (most recent call last):     File "C:\Python312\Lib\site-packages\pip\_vendor\pyproject_hooks\_in_process\_in_process.py", line 77, in _build_backend       obj = import_module(mod_path)             ^^^^^^^^^^^^^^^^^^^^^^^     File "C:\Python312\Lib\importlib\__init__.py", line 90, in import_module       return _bootstrap._gcd_import(name[level:], package, level)              ^^^^^^^^^^^^^^^^^^^^^^^^^^^^^^^^^^^^^^^^^^^^^^^^^^^^     File "<frozen importlib._bootstrap>", line 1387, in _gcd_import     File "<frozen importlib._bootstrap>", line 1360, in _find_and_load     File "<frozen importlib._bootstrap>", line 1310, in _find_and_load_unlocked     File "<frozen importlib._bootstrap>", line 488, in _call_with_frames_removed     File "<frozen importlib._bootstrap>", line 1387, in _gcd_import     File "<frozen importlib._bootstrap>", line 1360, in _find_and_load     File "<frozen importlib._bootstrap>", line 1331, in _find_and_load_unlocked     File "<frozen importlib._bootstrap>", line 935, in _load_unlocked     File "<frozen importlib._bootstrap_external>", line 999, in exec_module     File "<frozen importlib._bootstrap>", line 488, in _call_with_frames_removed     File "C:\Users\HP\AppData\Local\Temp\pip-build-env-z9j3sb81\overlay\Lib\site-packages\setuptools\__init__.py", line 9, in <module>       import distutils.core   ModuleNotFoundError: No module named 'distutils'      [end of output]      note: This error originates from a subprocess, and is likely not a problem with pip. System.Management.Automation.RemoteException [notice] A new release of pip is available: 24.3.1 -> 25.0.1 [notice] To update, run: python.exe -m pip install --upgrade pip error: subprocess-exited-with-error System.Management.Automation.RemoteException pip subprocess to install build dependencies did not run successfully. exit code: 2 System.Management.Automation.RemoteException See above for output. System.Management.Automation.RemoteException note: This error originates from a subprocess, and is likely not a problem with pip.
[2025-04-04 09:00:21][INFO] Installation des dépendances Python...
[2025-04-04 09:05:10][SUCCESS] Dépendances installées avec succès
[2025-04-04 09:05:47][ERROR] Erreur de configuration: Module pillow manquant
[2025-04-04 09:05:57][INFO] Installation des dépendances Python...
[2025-04-04 09:05:59][SUCCESS] Dépendances installées avec succès
[2025-04-04 09:06:02][INFO] Conversion des fichiers hérités...
[2025-04-04 09:06:02][SUCCESS] Conversion terminée avec succès
[2025-04-04 09:06:15][INFO] Lancement de l'analyse complète...
[2025-04-04 09:06:16][ERROR] Échec de l'analyse: Erreur lors de l'analyse
[2025-04-04 09:06:43][INFO] Traitement des cartes historiques (Tâche: thumbnails)...
[2025-04-04 09:06:44][ERROR] Échec du traitement: Erreur pendant le traitement
[2025-04-04 09:07:12][ERROR] Erreur de démarrage: Exception calling "Connect" with "2" argument(s): "Aucune connexion n’a pu être établie car l’ordinateur cible l’a expressément refusée. [::ffff:127.0.0.1]:5000"
[2025-04-04 09:08:22][INFO] Installation des dépendances Python...
[2025-04-04 09:08:26][SUCCESS] Dépendances installées avec succès
[2025-04-04 09:11:58][INFO] Installation des dépendances Python...
[2025-04-04 09:12:00][SUCCESS] Dépendances installées avec succès
[2025-04-04 09:17:55][ERROR] Erreur de configuration: Module pillow manquant
[2025-04-04 09:17:58][INFO] Installation des dépendances Python...
[2025-04-04 09:18:00][SUCCESS] Dépendances installées avec succès
[2025-04-04 09:18:02][INFO] Conversion des fichiers hérités...
[2025-04-04 09:18:02][SUCCESS] Conversion terminée avec succès
[2025-04-04 09:18:04][INFO] Lancement de l'analyse complète...
[2025-04-04 09:18:06][ERROR] Échec de l'analyse: Erreur lors de l'analyse
[2025-04-04 09:18:12][INFO] Traitement des cartes historiques (Tâche: all)...
[2025-04-04 09:18:12][ERROR] Échec du traitement: Erreur pendant le traitement
[2025-04-04 09:18:24][ERROR] Erreur de démarrage: Exception calling "Connect" with "2" argument(s): "Aucune connexion n’a pu être établie car l’ordinateur cible l’a expressément refusée. [::ffff:127.0.0.1]:5000"
[2025-04-04 09:18:47][ERROR] Erreur de configuration: Module pillow manquant
[2025-04-04 09:18:56][INFO] Installation des dépendances Python...
[2025-04-04 09:18:58][SUCCESS] Dépendances installées avec succès
[2025-04-04 09:19:07][INFO] Conversion des fichiers hérités...
[2025-04-04 09:19:07][SUCCESS] Conversion terminée avec succès
[2025-04-04 09:19:16][INFO] Lancement de l'analyse complète...
[2025-04-04 09:19:17][ERROR] Échec de l'analyse: Erreur lors de l'analyse
[2025-04-04 09:19:30][INFO] Traitement des cartes historiques (Tâche: all)...
[2025-04-04 09:19:30][ERROR] Échec du traitement: Erreur pendant le traitement
[2025-04-04 09:19:50][INFO] Traitement des cartes historiques (Tâche: all)...
[2025-04-04 09:19:50][ERROR] Échec du traitement: Erreur pendant le traitement
[2025-04-04 09:19:58][ERROR] Erreur de démarrage: Exception calling "Connect" with "2" argument(s): "Aucune connexion n’a pu être établie car l’ordinateur cible l’a expressément refusée. [::ffff:127.0.0.1]:5000"
[2025-04-04 09:24:09][ERROR] Erreur de configuration: Module pillow manquant
[2025-04-04 09:24:12][INFO] Installation des dépendances Python...
[2025-04-04 09:24:13][SUCCESS] Dépendances installées avec succès
[2025-04-04 09:24:16][INFO] Conversion des fichiers hérités...
[2025-04-04 09:24:16][SUCCESS] Conversion terminée avec succès
[2025-04-04 09:24:19][INFO] Lancement de l'analyse complète...
[2025-04-04 09:24:20][ERROR] Échec de l'analyse: Erreur lors de l'analyse
[2025-04-04 09:24:24][INFO] Traitement des cartes historiques (Tâche: all)...
[2025-04-04 09:24:25][ERROR] Échec du traitement: Erreur pendant le traitement
[2025-04-04 09:24:35][ERROR] Erreur de démarrage: Exception calling "Connect" with "2" argument(s): "Aucune connexion n’a pu être établie car l’ordinateur cible l’a expressément refusée. [::ffff:127.0.0.1]:5000"
[2025-04-04 09:25:41][ERROR] Erreur de configuration: Module pillow manquant
[2025-04-04 09:25:50][INFO] Installation des dépendances Python...
[2025-04-04 09:25:52][SUCCESS] Dépendances installées avec succès
[2025-04-04 09:26:01][INFO] Conversion des fichiers hérités...
[2025-04-04 09:26:01][SUCCESS] Conversion terminée avec succès
[2025-04-04 09:26:13][INFO] Lancement de l'analyse complète...
[2025-04-04 09:26:14][ERROR] Échec de l'analyse: Erreur lors de l'analyse
[2025-04-04 09:26:26][INFO] Traitement des cartes historiques (Tâche: all)...
[2025-04-04 09:26:27][ERROR] Échec du traitement: Erreur pendant le traitement
[2025-04-04 09:26:43][ERROR] Erreur de démarrage: Exception calling "Connect" with "2" argument(s): "Aucune connexion n’a pu être établie car l’ordinateur cible l’a expressément refusée. [::ffff:127.0.0.1]:5000"
[2025-04-04 09:32:46][ERROR] Erreur de configuration: Module pillow manquant
[2025-04-04 09:32:49][INFO] Installation des dépendances Python...
[2025-04-04 09:32:51][SUCCESS] Dépendances installées avec succès
[2025-04-04 09:32:57][INFO] Conversion des fichiers hérités...
[2025-04-04 09:32:57][ERROR] Erreur de conversion: Répertoire source introuvable
[2025-04-04 09:33:07][INFO] Lancement de l'analyse complète...
[2025-04-04 09:33:08][ERROR] Échec de l'analyse: Erreur lors de l'analyse
[2025-04-04 09:33:14][INFO] Traitement des cartes historiques (Tâche: all)...
[2025-04-04 09:33:15][ERROR] Échec du traitement: Erreur pendant le traitement
[2025-04-04 09:33:23][ERROR] Erreur de démarrage: Exception calling "Connect" with "2" argument(s): "Aucune connexion n’a pu être établie car l’ordinateur cible l’a expressément refusée. [::ffff:127.0.0.1]:5000"
[2025-04-04 09:33:31][ERROR] Erreur de configuration: Module pillow manquant
[2025-04-04 09:33:42][INFO] Installation des dépendances Python...
[2025-04-04 09:33:44][SUCCESS] Dépendances installées avec succès
[2025-04-04 09:33:59][INFO] Conversion des fichiers hérités...
[2025-04-04 09:33:59][ERROR] Erreur de conversion: Répertoire source introuvable
[2025-04-04 09:34:18][INFO] Lancement de l'analyse complète...
[2025-04-04 09:34:20][ERROR] Échec de l'analyse: Erreur lors de l'analyse
[2025-04-04 09:34:34][INFO] Traitement des cartes historiques (Tâche: all)...
[2025-04-04 09:34:35][ERROR] Échec du traitement: Erreur pendant le traitement
[2025-04-04 09:34:50][ERROR] Erreur de démarrage: Exception calling "Connect" with "2" argument(s): "Aucune connexion n’a pu être établie car l’ordinateur cible l’a expressément refusée. [::ffff:127.0.0.1]:5000"
[2025-04-04 09:35:07][ERROR] Le fichier C:\Users\HP\Desktop\Revoir-Histoire-Anciens-Batisseurs-master\tests\test_links.txt n'existe pas.
[2025-04-04 09:35:29][ERROR] Le fichier C:\Users\HP\Desktop\Revoir-Histoire-Anciens-Batisseurs-master\tests\test_links.txt n'existe pas.
[2025-04-04 09:40:20][SUCCESS] Environnement validé avec succès
[2025-04-04 09:40:32][INFO] Installation des dépendances Python...
[2025-04-04 09:40:34][SUCCESS] Dépendances installées avec succès
[2025-04-04 09:40:54][INFO] Conversion des fichiers hérités...
[2025-04-04 09:40:54][WARNING] Répertoire source créé : True
[2025-04-04 09:40:54][SUCCESS] Conversion réussie : C:\Users\HP\Desktop\Revoir-Histoire-Anciens-Batisseurs-master\data\sources\youtube.json
[2025-04-04 09:40:54][SUCCESS] Conversion réussie : C:\Users\HP\Desktop\Revoir-Histoire-Anciens-Batisseurs-master\data\sources\google.json
[2025-04-04 09:40:54][SUCCESS] Conversion terminée avec succès
[2025-04-04 09:41:05][INFO] Lancement de l'analyse complète...
[2025-04-04 09:41:05][WARNING] Fichier carte exemple créé
[2025-04-04 09:41:06][ERROR] Échec de l'analyse: Erreur dans analyze.py
[2025-04-04 09:41:21][INFO] Traitement des cartes historiques (Tâche: all)...
[2025-04-04 09:41:22][ERROR] Échec du traitement: Erreur pendant le traitement
[2025-04-04 09:41:42][SUCCESS] Interface web démarrée sur http://localhost:5000
[2025-04-04 09:42:32][SUCCESS] Conversion réussie : C:\Users\HP\Desktop\Revoir-Histoire-Anciens-Batisseurs-master\tests\test_output.json
